2020-11-26 08:14:50,385 - root - ERROR - (<class 'Exception'>, Exception('Test exception message.'), <traceback object at 0x7f7539cbfc00>)
Traceback (most recent call last):
  File "/usr/local/lib/python3.9/site-packages/engine_pin-0.2.10a4-py3.9.egg/pin/router.py", line 25, in wrapper_b
    return response_(func(*args))
  File "/var/app/pin/tests/ut/test_server.py", line 24, in exception
    raise Exception("Test exception message.")
Exception: Test exception message.
2020-11-30 08:58:15,348 - root - ERROR - (<class 'Exception'>, Exception('Test exception message.'), <traceback object at 0x7fab2e0a1480>)
Traceback (most recent call last):
  File "/usr/local/lib/python3.9/site-packages/engine_pin-0.2.10a5-py3.9.egg/pin/router.py", line 25, in wrapper_b
    return response_(func(*args))
  File "/var/app/pin/tests/ut/test_server.py", line 24, in exception
    raise Exception("Test exception message.")
Exception: Test exception message.
2020-11-30 09:03:59,895 - root - ERROR - (<class 'Exception'>, Exception('Test exception message.'), <traceback object at 0x7fe5c97ec240>)
Traceback (most recent call last):
  File "/usr/local/lib/python3.9/site-packages/engine_pin-0.2.10a5-py3.9.egg/pin/router.py", line 25, in wrapper_b
    return response_(func(*args))
  File "/var/app/pin/tests/ut/test_server.py", line 24, in exception
    raise Exception("Test exception message.")
Exception: Test exception message.
2020-11-30 09:06:56,695 - root - ERROR - (<class 'Exception'>, Exception('Test exception message.'), <traceback object at 0x7f870482b080>)
Traceback (most recent call last):
  File "/usr/local/lib/python3.9/site-packages/engine_pin-0.2.10a5-py3.9.egg/pin/router.py", line 25, in wrapper_b
    return response_(func(*args))
  File "/var/app/pin/tests/ut/test_server.py", line 24, in exception
    raise Exception("Test exception message.")
Exception: Test exception message.
2020-11-30 09:08:44,259 - root - ERROR - (<class 'Exception'>, Exception('Test exception message.'), <traceback object at 0x7fa2434e4c80>)
Traceback (most recent call last):
  File "/usr/local/lib/python3.9/site-packages/engine_pin-0.2.10a5-py3.9.egg/pin/router.py", line 25, in wrapper_b
    return response_(func(*args))
  File "/var/app/pin/tests/ut/test_server.py", line 24, in exception
    raise Exception("Test exception message.")
Exception: Test exception message.
2020-11-30 09:12:13,006 - root - ERROR - (<class 'Exception'>, Exception('Test exception message.'), <traceback object at 0x7f48e366ce80>)
Traceback (most recent call last):
  File "/usr/local/lib/python3.9/site-packages/engine_pin-0.2.10a5-py3.9.egg/pin/router.py", line 25, in wrapper_b
    return response_(func(*args))
  File "/var/app/pin/tests/ut/test_server.py", line 24, in exception
    raise Exception("Test exception message.")
Exception: Test exception message.
2020-11-30 09:13:41,986 - root - ERROR - (<class 'Exception'>, Exception('Test exception message.'), <traceback object at 0x7f7acffaf5c0>)
Traceback (most recent call last):
  File "/usr/local/lib/python3.9/site-packages/engine_pin-0.2.10a5-py3.9.egg/pin/router.py", line 25, in wrapper_b
    return response_(func(*args))
  File "/var/app/pin/tests/ut/test_server.py", line 24, in exception
    raise Exception("Test exception message.")
Exception: Test exception message.
2020-11-30 09:38:12,514 - root - ERROR - (<class 'Exception'>, Exception('Test exception message.'), <traceback object at 0x7fc08a49ebc0>)
Traceback (most recent call last):
  File "/usr/local/lib/python3.9/site-packages/engine_pin-0.2.10a6-py3.9.egg/pin/router.py", line 25, in wrapper_b
    return response_(func(*args))
  File "/var/app/pin/tests/ut/test_server.py", line 24, in exception
    raise Exception("Test exception message.")
Exception: Test exception message.
2020-11-30 09:43:50,328 - root - ERROR - (<class 'Exception'>, Exception('Test exception message.'), <traceback object at 0x7f9ad0269d80>)
Traceback (most recent call last):
  File "/usr/local/lib/python3.9/site-packages/engine_pin-0.2.10a7-py3.9.egg/pin/router.py", line 25, in wrapper_b
    return response_(func(*args))
  File "/var/app/pin/tests/ut/test_server.py", line 24, in exception
    raise Exception("Test exception message.")
Exception: Test exception message.
2020-11-30 14:38:24,596 - root - ERROR - (<class 'Exception'>, Exception('Test exception message.'), <traceback object at 0x7f7abe72a380>)
Traceback (most recent call last):
  File "/usr/local/lib/python3.9/site-packages/engine_pin-0.2.10a10-py3.9.egg/pin/router.py", line 25, in wrapper_b
    return response_(func(*args))
  File "/var/app/pin/tests/ut/test_server.py", line 24, in exception
    raise Exception("Test exception message.")
Exception: Test exception message.
2020-12-01 02:16:20,108 - root - ERROR - (<class 'Exception'>, Exception('Test exception message.'), <traceback object at 0x7f12ddb88600>)
Traceback (most recent call last):
  File "/usr/local/lib/python3.9/site-packages/engine_pin-0.2.10a11-py3.9.egg/pin/router.py", line 25, in wrapper_b
    return response_(func(*args))
  File "/var/app/pin/tests/ut/test_server.py", line 24, in exception
    raise Exception("Test exception message.")
Exception: Test exception message.
2020-12-01 02:55:43,398 - root - ERROR - (<class 'Exception'>, Exception('Test exception message.'), <traceback object at 0x7fa1e774b500>)
Traceback (most recent call last):
  File "/usr/local/lib/python3.9/site-packages/engine_pin-0.2.10a11-py3.9.egg/pin/router.py", line 25, in wrapper_b
    return response_(func(*args))
  File "/var/app/pin/tests/ut/test_server.py", line 24, in exception
    raise Exception("Test exception message.")
Exception: Test exception message.
2020-12-01 04:56:14,037 - root - ERROR - (<class 'Exception'>, Exception('Test exception message.'), <traceback object at 0x7f969912bd80>)
Traceback (most recent call last):
  File "/usr/local/lib/python3.9/site-packages/engine_pin-0.2.10a12-py3.9.egg/pin/router.py", line 25, in wrapper_b
    return response_(func(*args))
  File "/var/app/pin/tests/ut/test_server.py", line 24, in exception
    raise Exception("Test exception message.")
Exception: Test exception message.
2020-12-01 06:46:46,231 - root - ERROR - (<class 'Exception'>, Exception('Test exception message.'), <traceback object at 0x7f2586079900>)
Traceback (most recent call last):
  File "/usr/local/lib/python3.9/site-packages/engine_pin-0.2.10a13-py3.9.egg/pin/router.py", line 25, in wrapper_b
    return response_(func(*args))
  File "/var/app/pin/tests/ut/test_server.py", line 24, in exception
    raise Exception("Test exception message.")
Exception: Test exception message.
2020-12-01 06:48:03,964 - root - ERROR - (<class 'Exception'>, Exception('Test exception message.'), <traceback object at 0x7f0d955f41c0>)
Traceback (most recent call last):
  File "/usr/local/lib/python3.9/site-packages/engine_pin-0.2.10a13-py3.9.egg/pin/router.py", line 25, in wrapper_b
    return response_(func(*args))
  File "/var/app/pin/tests/ut/test_server.py", line 24, in exception
    raise Exception("Test exception message.")
Exception: Test exception message.
2020-12-01 06:49:47,664 - root - ERROR - (<class 'Exception'>, Exception('Test exception message.'), <traceback object at 0x7f131899cf80>)
Traceback (most recent call last):
  File "/usr/local/lib/python3.9/site-packages/engine_pin-0.2.10a13-py3.9.egg/pin/router.py", line 25, in wrapper_b
    return response_(func(*args))
  File "/var/app/pin/tests/ut/test_server.py", line 24, in exception
    raise Exception("Test exception message.")
Exception: Test exception message.
2020-12-01 06:58:57,162 - root - ERROR - (<class 'Exception'>, Exception('Test exception message.'), <traceback object at 0x7f7d5f410ac0>)
Traceback (most recent call last):
  File "/usr/local/lib/python3.9/site-packages/engine_pin-0.2.10a13-py3.9.egg/pin/router.py", line 25, in wrapper_b
    return response_(func(*args))
  File "/var/app/pin/tests/ut/test_server.py", line 24, in exception
    raise Exception("Test exception message.")
Exception: Test exception message.
2020-12-06 03:39:15,182 - root - ERROR - (<class 'Exception'>, Exception('Test exception message.'), <traceback object at 0x7f1c63d364c0>)
Traceback (most recent call last):
  File "/usr/local/lib/python3.9/site-packages/engine_pin-0.2.10a14-py3.9.egg/pin/router.py", line 25, in wrapper_b
    return response_(func(*args))
  File "/var/app/pin/tests/ut/test_server.py", line 24, in exception
    raise Exception("Test exception message.")
Exception: Test exception message.
2020-12-06 08:40:09,603 - root - ERROR - (<class 'Exception'>, Exception('Test exception message.'), <traceback object at 0x7fe91249a5c0>)
Traceback (most recent call last):
  File "/usr/local/lib/python3.9/site-packages/engine_pin-0.2.10a14-py3.9.egg/pin/router.py", line 25, in wrapper_b
    return response_(func(*args))
  File "/var/app/pin/tests/ut/test_server.py", line 24, in exception
    raise Exception("Test exception message.")
Exception: Test exception message.
2020-12-06 08:41:43,296 - root - ERROR - (<class 'Exception'>, Exception('Test exception message.'), <traceback object at 0x7f4b10770280>)
Traceback (most recent call last):
  File "/usr/local/lib/python3.9/site-packages/engine_pin-0.2.10a14-py3.9.egg/pin/router.py", line 25, in wrapper_b
    return response_(func(*args))
  File "/var/app/pin/tests/ut/test_server.py", line 24, in exception
    raise Exception("Test exception message.")
Exception: Test exception message.
2020-12-06 08:43:41,420 - root - ERROR - (<class 'Exception'>, Exception('Test exception message.'), <traceback object at 0x7fa58eeb88c0>)
Traceback (most recent call last):
  File "/usr/local/lib/python3.9/site-packages/engine_pin-0.2.10a14-py3.9.egg/pin/router.py", line 25, in wrapper_b
    return response_(func(*args))
  File "/var/app/pin/tests/ut/test_server.py", line 24, in exception
    raise Exception("Test exception message.")
Exception: Test exception message.
2020-12-06 08:48:52,945 - root - ERROR - (<class 'Exception'>, Exception('Test exception message.'), <traceback object at 0x7f732c214b00>)
Traceback (most recent call last):
  File "/usr/local/lib/python3.9/site-packages/engine_pin-0.2.10a14-py3.9.egg/pin/router.py", line 25, in wrapper_b
    return response_(func(*args))
  File "/var/app/pin/tests/ut/test_server.py", line 24, in exception
    raise Exception("Test exception message.")
Exception: Test exception message.
2020-12-06 09:01:49,238 - root - ERROR - (<class 'Exception'>, Exception('Test exception message.'), <traceback object at 0x7f97fb3a6200>)
Traceback (most recent call last):
  File "/usr/local/lib/python3.9/site-packages/engine_pin-0.2.10a14-py3.9.egg/pin/router.py", line 25, in wrapper_b
    return response_(func(*args))
  File "/var/app/pin/tests/ut/test_server.py", line 24, in exception
    raise Exception("Test exception message.")
Exception: Test exception message.
2020-12-06 09:14:26,694 - root - ERROR - (<class 'Exception'>, Exception('Test exception message.'), <traceback object at 0x7f5f3236b780>)
Traceback (most recent call last):
  File "/usr/local/lib/python3.9/site-packages/engine_pin-0.2.10a14-py3.9.egg/pin/router.py", line 25, in wrapper_b
    return response_(func(*args))
  File "/var/app/pin/tests/ut/test_server.py", line 24, in exception
    raise Exception("Test exception message.")
Exception: Test exception message.
2020-12-06 09:25:23,091 - root - ERROR - (<class 'Exception'>, Exception('Test exception message.'), <traceback object at 0x7f128cb23f00>)
Traceback (most recent call last):
  File "/usr/local/lib/python3.9/site-packages/engine_pin-0.2.10a14-py3.9.egg/pin/router.py", line 25, in wrapper_b
    return response_(func(*args))
  File "/var/app/pin/tests/ut/test_server.py", line 24, in exception
    raise Exception("Test exception message.")
Exception: Test exception message.
