2020-11-26 08:14:50,385 - root - ERROR - (<class 'Exception'>, Exception('Test exception message.'), <traceback object at 0x7f7539cbfc00>)
Traceback (most recent call last):
  File "/usr/local/lib/python3.9/site-packages/engine_pin-0.2.10a4-py3.9.egg/pin/router.py", line 25, in wrapper_b
    return response_(func(*args))
  File "/var/app/pin/tests/ut/test_server.py", line 24, in exception
    raise Exception("Test exception message.")
Exception: Test exception message.
